Workbook
Name Slicer_Country: #N/A
Name Slicer_Country1: #N/A
Name Slicer_Region: #N/A

Sheet Data
A1: Country | B1: Happiness Score | C1: GDP per Capita | D1: Social Support | E1: Healthy Life Expectancy | F1: Freedom | G1: Perceptions of Corruption | H1: Year | I1: Region | J1: Visible
A2: Finland | B2: 7.7406998 | C2: 1.8440535 | D2: 1.5723668 | E2: 0.69479257 | F2: 0.85929418 | G2: 0.54615778 | H2: 2025 | I2: Western Europe | J2: =SUBTOTAL(103,WHR_Data[[#This Row],[Country]]) -> 1
A3: Denmark | B3: 7.5826998 | C3: 1.9077977 | D3: 1.5203613 | E3: 0.69894445 | F3: 0.8227399 | G3: 0.54841286 | H3: 2025 | I3: Western Europe | J3: =SUBTOTAL(103,WHR_Data[[#This Row],[Country]]) -> 1
A4: Iceland | B4: 7.5251002 | C4: 1.880718 | D4: 1.6165254 | E4: 0.71834469 | F4: 0.81850868 | G4: 0.18247271 | H4: 2025 | I4: Western Europe | J4: =SUBTOTAL(103,WHR_Data[[#This Row],[Country]]) -> 1
A5: Sweden | B5: 7.3441 | C5: 1.8781456 | D5: 1.5008261 | E5: 0.72387147 | F5: 0.83826935 | G5: 0.52379549 | H5: 2025 | I5: Western Europe | J5: =SUBTOTAL(103,WHR_Data[[#This Row],[Country]]) -> 1
A6: Norway | B6: 7.3411002 | C6: 1.8029336 | D6: 1.5127928 | E6: 0.73981619 | F6: 0.64146286 | G6: 0.19282268 | H6: 2025 | I6: Western Europe | J6: =SUBTOTAL(103,WHR_Data[[#This Row],[Country]]) -> 1
A7: Netherlands | B7: 7.3193998 | C7: 1.9006567 | D7: 1.462047 | E7: 0.70588273 | F7: 0.72508126 | G7: 0.37242097 | H7: 2025 | I7: Western Europe | J7: =SUBTOTAL(103,WHR_Data[[#This Row],[Country]]) -> 1
A8: Norway | B8: 7.3017001 | C8: 1.9519556 | D8: 1.5165399 | E8: 0.70379221 | F8: 0.83537573 | G8: 0.48393255 | H8: 2025 | I8: Western Europe | J8: =SUBTOTAL(103,WHR_Data[[#This Row],[Country]]) -> 1
A9: Luxembourg | B9: 7.1219001 | C9: 2.1405189 | D9: 1.3546256 | E9: 0.70760393 | F9: 0.80121309 | G9: 0.43241102 | H9: 2025 | I9: Western Europe | J9: =SUBTOTAL(103,WHR_Data[[#This Row],[Country]]) -> 1
A10: Switzerland | B10: 7.0602002 | C10: 1.9702685 | D10: 1.4249322 | E10: 0.7467435 | F10: 0.75915956 | G10: 0.49761266 | H10: 2025 | I10: Western Europe | J10: =SUBTOTAL(103,WHR_Data[[#This Row],[Country]]) -> 1
A11: Australia | B11: 7.0569 | C11: 1.8542584 | D11: 1.4610913 | E11: 0.69201797 | F11: 0.75627065 | G11: 0.32335192 | H11: 2025 | I11: North America & ANZ | J11: =SUBTOTAL(103,WHR_Data[[#This Row],[Country]]) -> 1
A12: New Zealand | B12: 7.0292001 | C12: 1.8103489 | D12: 1.5269402 | E12: 0.67262149 | F12: 0.74554718 | G12: 0.48021689 | H12: 2025 | I12: North America & ANZ | J12: =SUBTOTAL(103,WHR_Data[[#This Row],[Country]]) -> 1
A13: Costa Rica | B13: 6.9554 | C13: 1.5606451 | D13: 1.3730104 | E13: 0.66084558 | F13: 0.79651153 | G13: 0.12294854 | H13: 2025 | I13: Latin America & Caribbean | J13: =SUBTOTAL(103,WHR_Data[[#This Row],[Country]]) -> 1
... A62: Honduras | B62: 5.9684 | C62: 1.0906942 | D62: 1.0354576 | E62: 0.50224245 | F62: 0.71987933 | G62: 0.08078099 | H62: 2025 | I62: Latin America & Caribbean | J62: =SUBTOTAL(103,WHR_Data[[#This Row],[Country]]) -> 1
A63: Bahrain | B63: 5.9590998 | H63: 2025 | I63: Middle East & North Africa | J63: =SUBTOTAL(103,WHR_Data[[#This Row],[Country]]) -> 1
A64: Croatia | B64: 5.9422998 | C64: 1.7100956 | D64: 1.4447548 | E64: 0.63660008 | F64: 0.4691875 | G64: 0.04285844 | H64: 2025 | I64: Central & Eastern Europe | J64: =SUBTOTAL(103,WHR_Data[[#This Row],[Country]]) -> 1
A65: Greece | B65: 5.9335999 | C65: 1.6839155 | D65: 1.2760926 | E65: 0.69617534 | F65: 0.33715591 | G65: 0.092573896 | H65: 2025 | I65: Western Europe | J65: =SUBTOTAL(103,WHR_Data[[#This Row],[Country]]) -> 1
A66: Bosnia and Herzegovina | B66: 5.8769999 | C66: 1.4647413 | D66: 1.3181261 | E66: 0.58742434 | F66: 0.62063795 | G66: 0 | H66: 2025 | I66: Central & Eastern Europe | J66: =SUBTOTAL(103,WHR_Data[[#This Row],[Country]]) -> 1
A67: Libya | B67: 5.8663001 | C67: 1.5256569 | D67: 1.0999953 | E67: 0.54969484 | F67: 0.59170967 | G67: 0.20356907 | H67: 2025 | I67: Middle East & North Africa | J67: =SUBTOTAL(103,WHR_Data[[#This Row],[Country]]) -> 1
A68: Jamaica | B68: 5.8417001 | C68: 1.280195 | D68: 1.3238065 | E68: 0.56663692 | F68: 0.64691824 | G68: 0.028065192 | H68: 2025 | I68: Latin America & Caribbean | J68: =SUBTOTAL(103,WHR_Data[[#This Row],[Country]]) -> 1
A69: Peru | B69: 5.8408999 | C69: 1.3706019 | D69: 1.1799687 | E69: 0.66154379 | F69: 0.61484373 | G69: 0.028730555 | H69: 2025 | I69: Latin America & Caribbean | J69: =SUBTOTAL(103,WHR_Data[[#This Row],[Country]]) -> 1
A70: Dominican Republic | B70: 5.8228002 | C70: 1.5166973 | D70: 1.271513 | E70: 0.5112381 | F70: 0.7298944 | G70: 0.19556351 | H70: 2025 | I70: Latin America & Caribbean | J70: =SUBTOTAL(103,WHR_Data[[#This Row],[Country]]) -> 1
A71: Mauritius | B71: 5.8164001 | C71: 1.5704201 | D71: 1.3577837 | E71: 0.48974645 | F71: 0.64079583 | G71: 0.11776748 | H71: 2025 | I71: Sub-Saharan Africa | J71: =SUBTOTAL(103,WHR_Data[[#This Row],[Country]]) -> 1
A72: Moldova | B72: 5.8158998 | C72: 1.3853644 | D72: 1.277184 | E72: 0.54165703 | F72: 0.69485605 | G72: 0.044482507 | H72: 2025 | I72: Central & Eastern Europe | J72: =SUBTOTAL(103,WHR_Data[[#This Row],[Country]]) -> 1
A73: Russia | B73: 5.7852998 | C73: 1.6421922 | D73: 1.3511909 | E73: 0.53135198 | F73: 0.55145341 | G73: 0.12052719 | H73: 2025 | I73: Commonwealth of Independent States | J73: =SUBTOTAL(103,WHR_Data[[#This Row],[Country]]) -> 1
A74: Bolivia | B74: 5.7842999 | C74: 1.2170526 | D74: 1.1794114 | E74: 0.48760787 | F74: 0.71946114 | G74: 0.060818609 | H74: 2025 | I74: Latin America & Caribbean | J74: =SUBTOTAL(103,WHR_Data[[#This Row],[Country]]) -> 1
A75: Ecuador | B75: 5.7245002 | C75: 1.3154677 | D75: 1.1506501 | E75: 0.6400609 | F75: 0.60608113 | G75: 0.078329697 | H75: 2025 | I75: Latin America & Caribbean | J75: =SUBTOTAL(103,WHR_Data[[#This Row],[Country]]) -> 1
... A88: Albania | B88: 5.3042002 | C88: 1.4378889 | D88: 0.9235726 | E88: 0.63798749 | F88: 0.68972975 | G88: 0.048980724 | H88: 2025 | I88: Central & Eastern Europe | J88: =SUBTOTAL(103,WHR_Data[[#This Row],[Country]]) -> 1
A89: Tajikistan | B89: 5.2807002 | H89: 2025 | I89: Commonwealth of Independent States | J89: =SUBTOTAL(103,WHR_Data[[#This Row],[Country]]) -> 1
A90: Congo (Brazzaville) | B90: 5.2214999 | C90: 0.89234102 | D90: 0.62188697 | E90: 0.30558527 | F90: 0.52273506 | G90: 0.13767824 | H90: 2025 | I90: Sub-Saharan Africa | J90: =SUBTOTAL(103,WHR_Data[[#This Row],[Country]]) -> 1
A91: Mozambique | B91: 5.2164001 | C91: 0.55976743 | D91: 0.88307136 | E91: 0.1555666 | F91: 0.72811127 | G91: 0.19617113 | H91: 2025 | I91: Sub-Saharan Africa | J91: =SUBTOTAL(103,WHR_Data[[#This Row],[Country]]) -> 1
A92: Georgia | B92: 5.1847 | C92: 1.4669232 | D92: 0.99001116 | E92: 0.52437627 | F92: 0.67981416 | G92: 0.17428675 | H92: 2025 | I92: Commonwealth of Independent States | J92: =SUBTOTAL(103,WHR_Data[[#This Row],[Country]]) -> 1
A93: Iraq | B93: 5.1659999 | C93: 1.2487026 | D93: 0.99594837 | E93: 0.49819964 | F93: 0.42452464 | G93: 0.047819857 | H93: 2025 | I93: Middle East & North Africa | J93: =SUBTOTAL(103,WHR_Data[[#This Row],[Country]]) -> 1
A94: Nepal | B94: 5.1584001 | C94: 0.96536392 | D94: 0.99018365 | E94: 0.44261762 | F94: 0.65291429 | G94: 0.11491369 | H94: 2025 | I94: South Asia | J94: =SUBTOTAL(103,WHR_Data[[#This Row],[Country]]) -> 1
A95: Laos | B95: 5.1388998 | C95: 1.2084683 | D95: 0.84629792 | E95: 0.42291266 | F95: 0.79646611 | G95: 0.16654132 | H95: 2025 | I95: Southeast Asia | J95: =SUBTOTAL(103,WHR_Data[[#This Row],[Country]]) -> 1
A96: Gabon | B96: 5.1062999 | C96: 1.4034375 | D96: 1.037624 | E96: 0.34429106 | F96: 0.51581484 | G96: 0.09986981 | H96: 2025 | I96: Sub-Saharan Africa | J96: =SUBTOTAL(103,WHR_Data[[#This Row],[Country]]) -> 1
A97: Ivory Coast | B97: 5.0801001 | C97: 1.0801312 | D97: 0.57763052 | E97: 0.28758216 | F97: 0.54695112 | G97: 0.1640697 | H97: 2025 | I97: Sub-Saharan Africa | J97: =SUBTOTAL(103,WHR_Data[[#This Row],[Country]]) -> 1
A98: Guinea | B98: 5.0233002 | C98: 0.83056736 | D98: 0.62161261 | E98: 0.23553006 | F98: 0.52128488 | G98: 0.10744683 | H98: 2025 | I98: Sub-Saharan Africa | J98: =SUBTOTAL(103,WHR_Data[[#This Row],[Country]]) -> 1
A99: Turkiye | B99: 4.9752998 | C99: 1.701578 | D99: 1.1750115 | E99: 0.63106775 | F99: 0.20207588 | G99: 0.11476535 | H99: 2025 | I99: Middle East & North Africa | J99: =SUBTOTAL(103,WHR_Data[[#This Row],[Country]]) -> 1
A100: Senegal | B100: 4.9685998 | C100: 0.92735916 | D100: 0.75067896 | E100: 0.39214456 | F100: 0.60675263 | G100: 0.06868311 | H100: 2025 | I100: Sub-Saharan Africa | J100: =SUBTOTAL(103,WHR_Data[[#This Row],[Country]]) -> 1
...

Sheet Dataset
A1: Country | B1: Happiness Score | C1: GDP | D1: Social Support | E1: Health | F1: Freedom | G1: Corruption | H1: Year
A2: Finland | B2: 7.7406998 | C2: 1.8440535 | D2: 1.5723668 | E2: 0.69479257 | F2: 0.85929418 | G2: 0.54615778 | H2: 2025
A3: Denmark | B3: 7.5826998 | C3: 1.9077977 | D3: 1.5203613 | E3: 0.69894445 | F3: 0.8227399 | G3: 0.54841286 | H3: 2025
A4: Iceland | B4: 7.5251002 | C4: 1.880718 | D4: 1.6165254 | E4: 0.71834469 | F4: 0.81850868 | G4: 0.18247271 | H4: 2025
A5: Sweden | B5: 7.3441 | C5: 1.8781456 | D5: 1.5008261 | E5: 0.72387147 | F5: 0.83826935 | G5: 0.52379549 | H5: 2025
A6: Norway | B6: 7.3411002 | C6: 1.8029336 | D6: 1.5127928 | E6: 0.73981619 | F6: 0.64146286 | G6: 0.19282268 | H6: 2025
A7: Netherlands | B7: 7.3193998 | C7: 1.9006567 | D7: 1.462047 | E7: 0.70588273 | F7: 0.72508126 | G7: 0.37242097 | H7: 2025
A8: Norway | B8: 7.3017001 | C8: 1.9519556 | D8: 1.5165399 | E8: 0.70379221 | F8: 0.83537573 | G8: 0.48393255 | H8: 2025
A9: Luxembourg | B9: 7.1219001 | C9: 2.1405189 | D9: 1.3546256 | E9: 0.70760393 | F9: 0.80121309 | G9: 0.43241102 | H9: 2025
A10: Switzerland | B10: 7.0602002 | C10: 1.9702685 | D10: 1.4249322 | E10: 0.7467435 | F10: 0.75915956 | G10: 0.49761266 | H10: 2025
A11: Australia | B11: 7.0569 | C11: 1.8542584 | D11: 1.4610913 | E11: 0.69201797 | F11: 0.75627065 | G11: 0.32335192 | H11: 2025
A12: New Zealand | B12: 7.0292001 | C12: 1.8103489 | D12: 1.5269402 | E12: 0.67262149 | F12: 0.74554718 | G12: 0.48021689 | H12: 2025
A13: Costa Rica | B13: 6.9554 | C13: 1.5606451 | D13: 1.3730104 | E13: 0.66084558 | F13: 0.79651153 | G13: 0.12294854 | H13: 2025
... A62: Honduras | B62: 5.9684 | C62: 1.0906942 | D62: 1.0354576 | E62: 0.50224245 | F62: 0.71987933 | G62: 0.08078099 | H62: 2025
A63: Bahrain | B63: 5.9590998 | H63: 2025
A64: Croatia | B64: 5.9422998 | C64: 1.7100956 | D64: 1.4447548 | E64: 0.63660008 | F64: 0.4691875 | G64: 0.04285844 | H64: 2025
A65: Greece | B65: 5.9335999 | C65: 1.6839155 | D65: 1.2760926 | E65: 0.69617534 | F65: 0.33715591 | G65: 0.092573896 | H65: 2025
A66: Bosnia and Herzegovina | B66: 5.8769999 | C66: 1.4647413 | D66: 1.3181261 | E66: 0.58742434 | F66: 0.62063795 | G66: 0 | H66: 2025
A67: Libya | B67: 5.8663001 | C67: 1.5256569 | D67: 1.0999953 | E67: 0.54969484 | F67: 0.59170967 | G67: 0.20356907 | H67: 2025
A68: Jamaica | B68: 5.8417001 | C68: 1.280195 | D68: 1.3238065 | E68: 0.56663692 | F68: 0.64691824 | G68: 0.028065192 | H68: 2025
A69: Peru | B69: 5.8408999 | C69: 1.3706019 | D69: 1.1799687 | E69: 0.66154379 | F69: 0.61484373 | G69: 0.028730555 | H69: 2025
A70: Dominican Republic | B70: 5.8228002 | C70: 1.5166973 | D70: 1.271513 | E70: 0.5112381 | F70: 0.7298944 | G70: 0.19556351 | H70: 2025
A71: Mauritius | B71: 5.8164001 | C71: 1.5704201 | D71: 1.3577837 | E71: 0.48974645 | F71: 0.64079583 | G71: 0.11776748 | H71: 2025
A72: Moldova | B72: 5.8158998 | C72: 1.3853644 | D72: 1.277184 | E72: 0.54165703 | F72: 0.69485605 | G72: 0.044482507 | H72: 2025
A73: Russia | B73: 5.7852998 | C73: 1.6421922 | D73: 1.3511909 | E73: 0.53135198 | F73: 0.55145341 | G73: 0.12052719 | H73: 2025
A74: Bolivia | B74: 5.7842999 | C74: 1.2170526 | D74: 1.1794114 | E74: 0.48760787 | F74: 0.71946114 | G74: 0.060818609 | H74: 2025
A75: Ecuador | B75: 5.7245002 | C75: 1.3154677 | D75: 1.1506501 | E75: 0.6400609 | F75: 0.60608113 | G75: 0.078329697 | H75: 2025
... A88: Albania | B88: 5.3042002 | C88: 1.4378889 | D88: 0.9235726 | E88: 0.63798749 | F88: 0.68972975 | G88: 0.048980724 | H88: 2025
A89: Tajikistan | B89: 5.2807002 | H89: 2025
A90: Congo (Brazzaville) | B90: 5.2214999 | C90: 0.89234102 | D90: 0.62188697 | E90: 0.30558527 | F90: 0.52273506 | G90: 0.13767824 | H90: 2025
A91: Mozambique | B91: 5.2164001 | C91: 0.55976743 | D91: 0.88307136 | E91: 0.1555666 | F91: 0.72811127 | G91: 0.19617113 | H91: 2025
A92: Georgia | B92: 5.1847 | C92: 1.4669232 | D92: 0.99001116 | E92: 0.52437627 | F92: 0.67981416 | G92: 0.17428675 | H92: 2025
A93: Iraq | B93: 5.1659999 | C93: 1.2487026 | D93: 0.99594837 | E93: 0.49819964 | F93: 0.42452464 | G93: 0.047819857 | H93: 2025
A94: Nepal | B94: 5.1584001 | C94: 0.96536392 | D94: 0.99018365 | E94: 0.44261762 | F94: 0.65291429 | G94: 0.11491369 | H94: 2025
A95: Laos | B95: 5.1388998 | C95: 1.2084683 | D95: 0.84629792 | E95: 0.42291266 | F95: 0.79646611 | G95: 0.16654132 | H95: 2025
A96: Gabon | B96: 5.1062999 | C96: 1.4034375 | D96: 1.037624 | E96: 0.34429106 | F96: 0.51581484 | G96: 0.09986981 | H96: 2025
A97: Ivory Coast | B97: 5.0801001 | C97: 1.0801312 | D97: 0.57763052 | E97: 0.28758216 | F97: 0.54695112 | G97: 0.1640697 | H97: 2025
A98: Guinea | B98: 5.0233002 | C98: 0.83056736 | D98: 0.62161261 | E98: 0.23553006 | F98: 0.52128488 | G98: 0.10744683 | H98: 2025
A99: Turkiye | B99: 4.9752998 | C99: 1.701578 | D99: 1.1750115 | E99: 0.63106775 | F99: 0.20207588 | G99: 0.11476535 | H99: 2025
A100: Senegal | B100: 4.9685998 | C100: 0.92735916 | D100: 0.75067896 | E100: 0.39214456 | F100: 0.60675263 | G100: 0.06868311 | H100: 2025
...

Sheet Pivot Tables
A1: World Happiness Report 2025 Pivot Tables | B1: Slicer-aware summary tables
A3: Top 10 Happiest Countries | B3: Column1 | D3: Bottom 10 Happiest Countries
A4: Country | B4: Happiness Score | D4: Country | E4: Happiness Score
A5: {=IFERROR(INDEX(_xlfn._xlws.FILTER(WHR_Data[Country],WHR_Data[Visible]=1),MATCH(B5,_xlfn._xlws.FILTER(WHR_Data[Happiness Score],WHR_Data[Visible]=1),0)),"")} -> Finland | B5: {=IFERROR(LARGE(_xlfn._xlws.FILTER(WHR_Data[Happiness Score],WHR_Data[Visible]=1),ROWS($B$5:B5)),"")} -> 7.7406998 | D5: {=IFERROR(INDEX(_xlfn._xlws.FILTER(WHR_Data[Country],WHR_Data[Visible]=1),MATCH(E5,_xlfn._xlws.FILTER(WHR_Data[Happiness Score],WHR_Data[Visible]=1),0)),"")} -> Afghanistan | E5: {=IFERROR(SMALL(_xlfn._xlws.FILTER(WHR_Data[Happiness Score],WHR_Data[Visible]=1),ROWS($E$5:E5)),"")} -> 1.721
A6: {=IFERROR(INDEX(_xlfn._xlws.FILTER(WHR_Data[Country],WHR_Data[Visible]=1),MATCH(B6,_xlfn._xlws.FILTER(WHR_Data[Happiness Score],WHR_Data[Visible]=1),0)),"")} -> Denmark | B6: {=IFERROR(LARGE(_xlfn._xlws.FILTER(WHR_Data[Happiness Score],WHR_Data[Visible]=1),ROWS($B$5:B6)),"")} -> 7.5826998 | D6: {=IFERROR(INDEX(_xlfn._xlws.FILTER(WHR_Data[Country],WHR_Data[Visible]=1),MATCH(E6,_xlfn._xlws.FILTER(WHR_Data[Happiness Score],WHR_Data[Visible]=1),0)),"")} -> Lebanon | E6: {=IFERROR(SMALL(_xlfn._xlws.FILTER(WHR_Data[Happiness Score],WHR_Data[Visible]=1),ROWS($E$5:E6)),"")} -> 2.7065001
A7: {=IFERROR(INDEX(_xlfn._xlws.FILTER(WHR_Data[Country],WHR_Data[Visible]=1),MATCH(B7,_xlfn._xlws.FILTER(WHR_Data[Happiness Score],WHR_Data[Visible]=1),0)),"")} -> Iceland | B7: {=IFERROR(LARGE(_xlfn._xlws.FILTER(WHR_Data[Happiness Score],WHR_Data[Visible]=1),ROWS($B$5:B7)),"")} -> 7.5251002 | D7: {=IFERROR(INDEX(_xlfn._xlws.FILTER(WHR_Data[Country],WHR_Data[Visible]=1),MATCH(E7,_xlfn._xlws.FILTER(WHR_Data[Happiness Score],WHR_Data[Visible]=1),0)),"")} -> Lesotho | E7: {=IFERROR(SMALL(_xlfn._xlws.FILTER(WHR_Data[Happiness Score],WHR_Data[Visible]=1),ROWS($E$5:E7)),"")} -> 3.1861999
A8: {=IFERROR(INDEX(_xlfn._xlws.FILTER(WHR_Data[Country],WHR_Data[Visible]=1),MATCH(B8,_xlfn._xlws.FILTER(WHR_Data[Happiness Score],WHR_Data[Visible]=1),0)),"")} -> Sweden | B8: {=IFERROR(LARGE(_xlfn._xlws.FILTER(WHR_Data[Happiness Score],WHR_Data[Visible]=1),ROWS($B$5:B8)),"")} -> 7.3441 | D8: {=IFERROR(INDEX(_xlfn._xlws.FILTER(WHR_Data[Country],WHR_Data[Visible]=1),MATCH(E8,_xlfn._xlws.FILTER(WHR_Data[Happiness Score],WHR_Data[Visible]=1),0)),"")} -> Sierra Leone | E8: {=IFERROR(SMALL(_xlfn._xlws.FILTER(WHR_Data[Happiness Score],WHR_Data[Visible]=1),ROWS($E$5:E8)),"")} -> 3.2451999
A9: {=IFERROR(INDEX(_xlfn._xlws.FILTER(WHR_Data[Country],WHR_Data[Visible]=1),MATCH(B9,_xlfn._xlws.FILTER(WHR_Data[Happiness Score],WHR_Data[Visible]=1),0)),"")} -> Norway | B9: {=IFERROR(LARGE(_xlfn._xlws.FILTER(WHR_Data[Happiness Score],WHR_Data[Visible]=1),ROWS($B$5:B9)),"")} -> 7.3411002 | D9: {=IFERROR(INDEX(_xlfn._xlws.FILTER(WHR_Data[Country],WHR_Data[Visible]=1),MATCH(E9,_xlfn._xlws.FILTER(WHR_Data[Happiness Score],WHR_Data[Visible]=1),0)),"")} -> Congo (Kinshasa) | E9: {=IFERROR(SMALL(_xlfn._xlws.FILTER(WHR_Data[Happiness Score],WHR_Data[Visible]=1),ROWS($E$5:E9)),"")} -> 3.2953999
A10: {=IFERROR(INDEX(_xlfn._xlws.FILTER(WHR_Data[Country],WHR_Data[Visible]=1),MATCH(B10,_xlfn._xlws.FILTER(WHR_Data[Happiness Score],WHR_Data[Visible]=1),0)),"")} -> Netherlands | B10: {=IFERROR(LARGE(_xlfn._xlws.FILTER(WHR_Data[Happiness Score],WHR_Data[Visible]=1),ROWS($B$5:B10)),"")} -> 7.3193998 | D10: {=IFERROR(INDEX(_xlfn._xlws.FILTER(WHR_Data[Country],WHR_Data[Visible]=1),MATCH(E10,_xlfn._xlws.FILTER(WHR_Data[Happiness Score],WHR_Data[Visible]=1),0)),"")} -> Zimbabwe | E10: {=IFERROR(SMALL(_xlfn._xlws.FILTER(WHR_Data[Happiness Score],WHR_Data[Visible]=1),ROWS($E$5:E10)),"")} -> 3.3411
A11: {=IFERROR(INDEX(_xlfn._xlws.FILTER(WHR_Data[Country],WHR_Data[Visible]=1),MATCH(B11,_xlfn._xlws.FILTER(WHR_Data[Happiness Score],WHR_Data[Visible]=1),0)),"")} -> Norway | B11: {=IFERROR(LARGE(_xlfn._xlws.FILTER(WHR_Data[Happiness Score],WHR_Data[Visible]=1),ROWS($B$5:B11)),"")} -> 7.3017001 | D11: {=IFERROR(INDEX(_xlfn._xlws.FILTER(WHR_Data[Country],WHR_Data[Visible]=1),MATCH(E11,_xlfn._xlws.FILTER(WHR_Data[Happiness Score],WHR_Data[Visible]=1),0)),"")} -> Botswana | E11: {=IFERROR(SMALL(_xlfn._xlws.FILTER(WHR_Data[Happiness Score],WHR_Data[Visible]=1),ROWS($E$5:E11)),"")} -> 3.3834
A12: {=IFERROR(INDEX(_xlfn._xlws.FILTER(WHR_Data[Country],WHR_Data[Visible]=1),MATCH(B12,_xlfn._xlws.FILTER(WHR_Data[Happiness Score],WHR_Data[Visible]=1),0)),"")} -> Luxembourg | B12: {=IFERROR(LARGE(_xlfn._xlws.FILTER(WHR_Data[Happiness Score],WHR_Data[Visible]=1),ROWS($B$5:B12)),"")} -> 7.1219001 | D12: {=IFERROR(INDEX(_xlfn._xlws.FILTER(WHR_Data[Country],WHR_Data[Visible]=1),MATCH(E12,_xlfn._xlws.FILTER(WHR_Data[Happiness Score],WHR_Data[Visible]=1),0)),"")} -> Malawi | E12: {=IFERROR(SMALL(_xlfn._xlws.FILTER(WHR_Data[Happiness Score],WHR_Data[Visible]=1),ROWS($E$5:E12)),"")} -> 3.421
A13: {=IFERROR(INDEX(_xlfn._xlws.FILTER(WHR_Data[Country],WHR_Data[Visible]=1),MATCH(B13,_xlfn._xlws.FILTER(WHR_Data[Happiness Score],WHR_Data[Visible]=1),0)),"")} -> Switzerland | B13: {=IFERROR(LARGE(_xlfn._xlws.FILTER(WHR_Data[Happiness Score],WHR_Data[Visible]=1),ROWS($B$5:B13)),"")} -> 7.0602002 | D13: {=IFERROR(INDEX(_xlfn._xlws.FILTER(WHR_Data[Country],WHR_Data[Visible]=1),MATCH(E13,_xlfn._xlws.FILTER(WHR_Data[Happiness Score],WHR_Data[Visible]=1),0)),"")} -> Eswatini | E13: {=IFERROR(SMALL(_xlfn._xlws.FILTER(WHR_Data[Happiness Score],WHR_Data[Visible]=1),ROWS($E$5:E13)),"")} -> 3.5020001
A14: {=IFERROR(INDEX(_xlfn._xlws.FILTER(WHR_Data[Country],WHR_Data[Visible]=1),MATCH(B14,_xlfn._xlws.FILTER(WHR_Data[Happiness Score],WHR_Data[Visible]=1),0)),"")} -> Australia | B14: {=IFERROR(LARGE(_xlfn._xlws.FILTER(WHR_Data[Happiness Score],WHR_Data[Visible]=1),ROWS($B$5:B14)),"")} -> 7.0569 | D14: {=IFERROR(INDEX(_xlfn._xlws.FILTER(WHR_Data[Country],WHR_Data[Visible]=1),MATCH(E14,_xlfn._xlws.FILTER(WHR_Data[Happiness Score],WHR_Data[Visible]=1),0)),"")} -> Zambia | E14: {=IFERROR(SMALL(_xlfn._xlws.FILTER(WHR_Data[Happiness Score],WHR_Data[Visible]=1),ROWS($E$5:E14)),"")} -> 3.5023999
A17: Region | B17: Average Happiness Score | C17: Average GDP per Capita | D17: Average Healthy Life Expectancy | F17: Region | G17: Country Count
A18: Western Europe | B18: =IFERROR(AVERAGEIFS(WHR_Data[Happiness Score],WHR_Data[Region],$A18,WHR_Data[Visible],1),"") -> 6.8653238 | C18: =IFERROR(AVERAGEIFS(WHR_Data[GDP per Capita],WHR_Data[Region],$A18,WHR_Data[Visible],1),"") -> 1.8699819 | D18: =IFERROR(AVERAGEIFS(WHR_Data[Healthy Life Expectancy],WHR_Data[Region],$A18,WHR_Data[Visible],1),"") -> 0.71057394 | F18: Western Europe | G18: {=IFERROR(ROWS(_xlfn.UNIQUE(_xlfn._xlws.FILTER(WHR_Data[Country],(WHR_Data[Visible]=1)*(WHR_Data[Region]=$F18)))),0)} -> 20
A19: Central & Eastern Europe | B19: =IFERROR(AVERAGEIFS(WHR_Data[Happiness Score],WHR_Data[Region],$A19,WHR_Data[Visible],1),"") -> 6.0839211 | C19: =IFERROR(AVERAGEIFS(WHR_Data[GDP per Capita],WHR_Data[Region],$A19,WHR_Data[Visible],1),"") -> 1.6092749 | D19: =IFERROR(AVERAGEIFS(WHR_Data[Healthy Life Expectancy],WHR_Data[Region],$A19,WHR_Data[Visible],1),"") -> 0.60172974 | F19: Central & Eastern Europe | G19: {=IFERROR(ROWS(_xlfn.UNIQUE(_xlfn._xlws.FILTER(WHR_Data[Country],(WHR_Data[Visible]=1)*(WHR_Data[Region]=$F19)))),0)} -> 19
A20: North America & ANZ | B20: =IFERROR(AVERAGEIFS(WHR_Data[Happiness Score],WHR_Data[Region],$A20,WHR_Data[Visible],1),"") -> 6.9276251 | C20: =IFERROR(AVERAGEIFS(WHR_Data[GDP per Capita],WHR_Data[Region],$A20,WHR_Data[Visible],1),"") -> 1.8607978 | D20: =IFERROR(AVERAGEIFS(WHR_Data[Healthy Life Expectancy],WHR_Data[Region],$A20,WHR_Data[Visible],1),"") -> 0.65201546 | F20: North America & ANZ | G20: {=IFERROR(ROWS(_xlfn.UNIQUE(_xlfn._xlws.FILTER(WHR_Data[Country],(WHR_Data[Visible]=1)*(WHR_Data[Region]=$F20)))),0)} -> 4
A21: Latin America & Caribbean | B21: =IFERROR(AVERAGEIFS(WHR_Data[Happiness Score],WHR_Data[Region],$A21,WHR_Data[Visible],1),"") -> 6.1433684 | C21: =IFERROR(AVERAGEIFS(WHR_Data[GDP per Capita],WHR_Data[Region],$A21,WHR_Data[Visible],1),"") -> 1.3281066 | D21: =IFERROR(AVERAGEIFS(WHR_Data[Healthy Life Expectancy],WHR_Data[Region],$A21,WHR_Data[Visible],1),"") -> 0.5710916 | F21: Latin America & Caribbean | G21: {=IFERROR(ROWS(_xlfn.UNIQUE(_xlfn._xlws.FILTER(WHR_Data[Country],(WHR_Data[Visible]=1)*(WHR_Data[Region]=$F21)))),0)} -> 19
A22: Middle East & North Africa | B22: =IFERROR(AVERAGEIFS(WHR_Data[Happiness Score],WHR_Data[Region],$A22,WHR_Data[Visible],1),"") -> 5.0660563 | C22: =IFERROR(AVERAGEIFS(WHR_Data[GDP per Capita],WHR_Data[Region],$A22,WHR_Data[Visible],1),"") -> 1.4212275 | D22: =IFERROR(AVERAGEIFS(WHR_Data[Healthy Life Expectancy],WHR_Data[Region],$A22,WHR_Data[Visible],1),"") -> 0.53795556 | F22: Middle East & North Africa | G22: {=IFERROR(ROWS(_xlfn.UNIQUE(_xlfn._xlws.FILTER(WHR_Data[Country],(WHR_Data[Visible]=1)*(WHR_Data[Region]=$F22)))),0)} -> 16
A23: East Asia | B23: =IFERROR(AVERAGEIFS(WHR_Data[Happiness Score],WHR_Data[Region],$A23,WHR_Data[Visible],1),"") -> 5.9344167 | C23: =IFERROR(AVERAGEIFS(WHR_Data[GDP per Capita],WHR_Data[Region],$A23,WHR_Data[Visible],1),"") -> 1.7000918 | D23: =IFERROR(AVERAGEIFS(WHR_Data[Healthy Life Expectancy],WHR_Data[Region],$A23,WHR_Data[Visible],1),"") -> 0.68180699 | F23: East Asia | G23: {=IFERROR(ROWS(_xlfn.UNIQUE(_xlfn._xlws.FILTER(WHR_Data[Country],(WHR_Data[Visible]=1)*(WHR_Data[Region]=$F23)))),0)} -> 6
A24: Southeast Asia | B24: =IFERROR(AVERAGEIFS(WHR_Data[Happiness Score],WHR_Data[Region],$A24,WHR_Data[Visible],1),"") -> 5.5519 | C24: =IFERROR(AVERAGEIFS(WHR_Data[GDP per Capita],WHR_Data[Region],$A24,WHR_Data[Visible],1),"") -> 1.3743534 | D24: =IFERROR(AVERAGEIFS(WHR_Data[Healthy Life Expectancy],WHR_Data[Region],$A24,WHR_Data[Visible],1),"") -> 0.52011009 | F24: Southeast Asia | G24: {=IFERROR(ROWS(_xlfn.UNIQUE(_xlfn._xlws.FILTER(WHR_Data[Country],(WHR_Data[Visible]=1)*(WHR_Data[Region]=$F24)))),0)} -> 9
A25: South Asia | B25: =IFERROR(AVERAGEIFS(WHR_Data[Happiness Score],WHR_Data[Region],$A25,WHR_Data[Visible],1),"") -> 3.8957 | C25: =IFERROR(AVERAGEIFS(WHR_Data[GDP per Capita],WHR_Data[Region],$A25,WHR_Data[Visible],1),"") -> 1.0517995 | D25: =IFERROR(AVERAGEIFS(WHR_Data[Healthy Life Expectancy],WHR_Data[Region],$A25,WHR_Data[Visible],1),"") -> 0.42024081 | F25: South Asia | G25: {=IFERROR(ROWS(_xlfn.UNIQUE(_xlfn._xlws.FILTER(WHR_Data[Country],(WHR_Data[Visible]=1)*(WHR_Data[Region]=$F25)))),0)} -> 6
A26: Commonwealth of Independent States | B26: =IFERROR(AVERAGEIFS(WHR_Data[Happiness Score],WHR_Data[Region],$A26,WHR_Data[Visible],1),"") -> 5.586875 | C26: =IFERROR(AVERAGEIFS(WHR_Data[GDP per Capita],WHR_Data[Region],$A26,WHR_Data[Visible],1),"") -> 1.4105831 | D26: =IFERROR(AVERAGEIFS(WHR_Data[Healthy Life Expectancy],WHR_Data[Region],$A26,WHR_Data[Visible],1),"") -> 0.54819392 | F26: Commonwealth of Independent States | G26: {=IFERROR(ROWS(_xlfn.UNIQUE(_xlfn._xlws.FILTER(WHR_Data[Country],(WHR_Data[Visible]=1)*(WHR_Data[Region]=$F26)))),0)} -> 8
A27: Sub-Saharan Africa | B27: =IFERROR(AVERAGEIFS(WHR_Data[Happiness Score],WHR_Data[Region],$A27,WHR_Data[Visible],1),"") -> 4.32978 | C27: =IFERROR(AVERAGEIFS(WHR_Data[GDP per Capita],WHR_Data[Region],$A27,WHR_Data[Visible],1),"") -> 0.90417171 | D27: =IFERROR(AVERAGEIFS(WHR_Data[Healthy Life Expectancy],WHR_Data[Region],$A27,WHR_Data[Visible],1),"") -> 0.29760955 | F27: Sub-Saharan Africa | G27: {=IFERROR(ROWS(_xlfn.UNIQUE(_xlfn._xlws.FILTER(WHR_Data[Country],(WHR_Data[Visible]=1)*(WHR_Data[Region]=$F27)))),0)} -> 35

Sheet KPIs
A1: World Happiness Report 2025 KPIs | B1: Last updated: 2026-05-23
A3: Total Number of Countries | B3: {=IFERROR(ROWS(_xlfn.UNIQUE(_xlfn._xlws.FILTER(WHR_Data[Country],WHR_Data[Visible]=1))),0)} -> 142 | D3: Data Note
A4: Highest Happiness Score | B4: =IFERROR(_xlfn.MAXIFS(WHR_Data[Happiness Score],WHR_Data[Visible],1),0) -> 7.7406998 | D4: Regions are analyst-assigned WHR-style groupings for dashboard slicing.
A5: Lowest Happiness Score | B5: =IFERROR(_xlfn.MINIFS(WHR_Data[Happiness Score],WHR_Data[Visible],1),0) -> 1.721 | D5: Raw records: 143
A6: Average Happiness Score | B6: =IFERROR(AVERAGEIFS(WHR_Data[Happiness Score],WHR_Data[Visible],1),0) -> 5.527572 | D6: Unique countries: 142
A7: Highest GDP per Capita | B7: =IFERROR(_xlfn.MAXIFS(WHR_Data[GDP per Capita],WHR_Data[Visible],1),0) -> 2.1405189 | D7: Duplicate countries retained in raw data: Norway
A8: Average Healthy Life Expectancy | B8: =IFERROR(AVERAGEIFS(WHR_Data[Healthy Life Expectancy],WHR_Data[Visible],1),0) -> 0.5207803 | D8: Use slicers on Dashboard to filter all KPI and chart outputs.

Sheet Charts
A1: World Happiness Report 2025 Charts | B1: Dynamic visuals powered by slicer-aware source tables | R1: Country | S1: GDP per Capita | T1: Happiness Score | V1: Country | W1: Social Support | X1: Happiness Score
R2: {=IFERROR(_xlfn.SORTBY(_xlfn._xlws.FILTER(CHOOSE({1,2,3},WHR_Data[Country],WHR_Data[GDP per Capita],WHR_Data[Happiness Score]),WHR_Data[Visible]=1),_xlfn._xlws.FILTER(WHR_Data[GDP per Capita],WHR_Data[Visible]=1),1),"")} -> Venezuela | S2: 0 | T2: 5.6066999 | V2: {=IFERROR(_xlfn.SORTBY(_xlfn._xlws.FILTER(CHOOSE({1,2,3},WHR_Data[Country],WHR_Data[Social Support],WHR_Data[Happiness Score]),WHR_Data[Visible]=1),_xlfn._xlws.FILTER(WHR_Data[Social Support],WHR_Data[Visible]=1),1),"")} -> Afghanistan | W2: 0 | X2: 1.721
R3: Congo (Kinshasa) | S3: 0.53367001 | T3: 3.2953999 | V3: Benin | W3: 0.12834492 | X3: 4.3773999
R4: Mozambique | S4: 0.55976743 | T4: 5.2164001 | V4: Bangladesh | W4: 0.24916358 | X4: 3.8859
R5: Niger | S5: 0.57284975 | T5: 4.5563002 | V5: Comoros | W5: 0.32799539 | X5: 3.5662999
R6: Chad | S6: 0.6033026 | T6: 4.4713001 | V6: Malawi | W6: 0.4103753 | X6: 3.421
R7: Malawi | S7: 0.61691111 | T7: 3.421 | V7: Morocco | W7: 0.47105265 | X7: 4.7947001
R8: Liberia | S8: 0.61877793 | T8: 4.2686 | V8: Sierra Leone | W8: 0.56597745 | X8: 3.2451999
R9: Madagascar | S9: 0.62790692 | T9: 4.2279 | V9: Lebanon | W9: 0.57671291 | X9: 2.7065001
R10: Afghanistan | S10: 0.62813818 | T10: 1.721 | V10: Ivory Coast | W10: 0.57763052 | X10: 5.0801001
R11: Sierra Leone | S11: 0.6542784 | T11: 3.2451999 | V11: Togo | W11: 0.58610827 | X11: 4.2140999
R12: Yemen | S12: 0.67127901 | T12: 3.5610001 | V12: Pakistan | W12: 0.60037744 | X12: 4.6567001
R13: Mali | S13: 0.74740672 | T13: 4.2319999 | V13: Guinea | W13: 0.62161261 | X13: 5.0233002
R14: Zimbabwe | S14: 0.74833721 | T14: 3.3411 | V14: Congo (Brazzaville) | W14: 0.62188697 | X14: 5.2214999
... R144: Tajikistan | S144: 0 | T144: 5.2807002 | V144: Tajikistan | W144: 0 | X144: 5.2807002

Sheet Dashboard
A1: World Happiness Report 2025 Dashboard | B1: Interactive analysis | Last updated: 2026-05-23
A2: Use the Region and Country slicers to filter all KPI cards, summary tables, and charts.
A4: Total Countries | D4: Highest Happiness | G4: Lowest Happiness | J4: Average Happiness | M4: Highest GDP / Capita
A6: =KPIs!B3 -> 142 | D6: =KPIs!B4 -> 7.7406998 | G6: =KPIs!B5 -> 1.721 | J6: =KPIs!B6 -> 5.527572 | M6: =KPIs!B7 -> 2.1405189
A9: Avg Healthy Life Exp.
D10: Decision note | E10: The dashboard is slicer-aware through the Data table Visible helper; raw records remain on Data.
A11: =KPIs!B8 -> 0.5207803
