Workbook

Sheet WHR_Comparison_2024_vs_2025
A1: WHR_Comparison_2024 vs 2025
A2: Country | B2: Happiness Score_2024 | C2: GDP_2024 | D2: Social Support_2024 | E2: Health_2024 | F2: Freedom_2024 | G2: Corruption_2024 | H2: Year_2024 | I2: Happiness Score_2025 | J2: GDP_2025 | K2: Social Support_2025 | L2: Health_2025 | M2: Freedom_2025 | N2: Corruption_2025 | O2: Year_2025 | P2: Score_Change
A3: Finland | B3: 7.8042002 | C3: 1.8883804 | D3: 1.5848997 | E3: 0.53457367 | F3: 0.77150995 | G3: 0.53529859 | H3: 2024 | I3: 7.7406998 | J3: 1.8440535 | K3: 1.5723668 | L3: 0.69479257 | M3: 0.85929418 | N3: 0.54615778 | O3: 2025 | P3: -0.0635
A4: Denmark | B4: 7.5864 | C4: 1.9494056 | D4: 1.5478748 | E4: 0.53730249 | F4: 0.73441589 | G4: 0.52522117 | H4: 2024 | I4: 7.5826998 | J4: 1.9077977 | K4: 1.5203613 | L4: 0.69894445 | M4: 0.8227399 | N4: 0.54841286 | O4: 2025 | P4: -0.0037
A5: Iceland | B5: 7.5296001 | C5: 1.9255077 | D5: 1.6196665 | E5: 0.5590964 | F5: 0.73816371 | G5: 0.18711878 | H5: 2024 | I5: 7.5251002 | J5: 1.880718 | K5: 1.6165254 | L5: 0.71834469 | M5: 0.81850868 | N5: 0.18247271 | O5: 2025 | P5: -0.0045
A6: Norway | B6: 7.4728999 | C6: 1.833398 | D6: 1.5206739 | E6: 0.57673001 | F6: 0.56851828 | G6: 0.15829206 | H6: 2024 | I6: 7.3411002 | J6: 1.8029336 | K6: 1.5127928 | L6: 0.73981619 | M6: 0.64146286 | N6: 0.19282268 | O6: 2025 | P6: -0.1318
A7: Netherlands | B7: 7.4029999 | C7: 1.9422739 | D7: 1.488228 | E7: 0.54547304 | F7: 0.67232722 | G7: 0.39406165 | H7: 2024 | I7: 7.3193998 | J7: 1.9006567 | K7: 1.462047 | L7: 0.70588273 | M7: 0.72508126 | N7: 0.37242097 | O7: 2025 | P7: -0.0836
A8: Sweden | B8: 7.3951998 | C8: 1.9209502 | D8: 1.510329 | E8: 0.56182474 | F8: 0.75362921 | G8: 0.52046913 | H8: 2024 | I8: 7.3441 | J8: 1.8781456 | K8: 1.5008261 | L8: 0.72387147 | M8: 0.83826935 | N8: 0.52379549 | O8: 2025 | P8: -0.0511
A9: Switzerland | B9: 7.2400999 | C9: 2.0218031 | D9: 1.462816 | E9: 0.58225435 | F9: 0.67791533 | G9: 0.47470021 | H9: 2024 | I9: 7.0602002 | J9: 1.9702685 | K9: 1.4249322 | L9: 0.7467435 | M9: 0.75915956 | N9: 0.49761266 | O9: 2025 | P9: -0.1799
A10: Luxembourg | B10: 7.2279 | C10: 2.1996644 | D10: 1.3568785 | E10: 0.54887843 | F10: 0.70967185 | G10: 0.41837958 | H10: 2024 | I10: 7.1219001 | J10: 2.1405189 | K10: 1.3546256 | L10: 0.70760393 | M10: 0.80121309 | N10: 0.43241102 | O10: 2025 | P10: -0.106
A11: New Zealand | B11: 7.1229 | C11: 1.8417042 | D11: 1.5435456 | E11: 0.51277792 | F11: 0.67192692 | G11: 0.4712207 | H11: 2024 | I11: 7.0292001 | J11: 1.8103489 | K11: 1.5269402 | L11: 0.67262149 | M11: 0.74554718 | N11: 0.48021689 | O11: 2025 | P11: -0.0937
A12: Austria | B12: 7.0973001 | C12: 1.9267181 | D12: 1.3819747 | E12: 0.53457516 | F12: 0.62956059 | G12: 0.30965307 | H12: 2024 | I12: 6.9046998 | J12: 1.8852654 | K12: 1.3363961 | L12: 0.69617385 | M12: 0.7027449 | N12: 0.30455476 | O12: 2025 | P12: -0.1926
A13: Australia | B13: 7.0946002 | C13: 1.898795 | D13: 1.4967434 | E13: 0.5318476 | F13: 0.6767512 | G13: 0.31026807 | H13: 2024 | I13: 7.0569 | J13: 1.8542584 | K13: 1.4610913 | L13: 0.69201797 | M13: 0.75627065 | N13: 0.32335192 | O13: 2025 | P13: -0.0377
A14: Canada | B14: 6.9607 | C14: 1.8814389 | D14: 1.4839185 | E14: 0.5413866 | F14: 0.65581697 | G14: 0.3644926 | H14: 2024 | I14: 6.8996 | J14: 1.8397207 | K14: 1.4586304 | L14: 0.70102102 | M14: 0.73007637 | N14: 0.36821935 | O14: 2025 | P14: -0.0611
... A40: Latvia | B40: 6.2126999 | C40: 1.7371428 | D40: 1.5049732 | E40: 0.40516222 | F40: 0.58015084 | G40: 0.070794009 | H40: 2024 | I40: 6.2344999 | J40: 1.7002943 | K40: 1.5084777 | L40: 0.56384015 | M40: 0.66628981 | N40: 0.078438014 | O40: 2025 | P40: 0.0218
A41: Bahrain | B41: 6.1732001 | C41: 1.88256 | D41: 1.2693384 | E41: 0.38948527 | F41: 0.7483083 | G41: 0.13780326 | H41: 2024 | I41: 5.9590998 | O41: 2025 | P41: -0.2141
A42: Guatemala | B42: 6.1503 | C42: 1.2871797 | D42: 1.188224 | E42: 0.30978888 | F42: 0.63119769 | G42: 0.06626451 | H42: 2024 | I42: 6.2870002 | J42: 1.2595253 | K42: 1.1688857 | L42: 0.46691173 | M42: 0.73530352 | N42: 0.07777147 | O42: 2025 | P42: 0.1367
A43: Kazakhstan | B43: 6.1438999 | C43: 1.6638873 | D43: 1.4906219 | E43: 0.38885146 | F43: 0.6275636 | G43: 0.14871794 | H43: 2024 | I43: 6.1875 | J43: 1.6224951 | K43: 1.4566449 | L43: 0.55558097 | M43: 0.73258322 | N43: 0.11975425 | O43: 2025 | P43: 0.0436
A44: Serbia | B44: 6.1436 | C44: 1.5519584 | D44: 1.3431039 | E44: 0.42388743 | F44: 0.61665088 | G44: 0.080694348 | H44: 2024 | I44: 6.4108 | J44: 1.5378245 | K44: 1.3914882 | L44: 0.58534294 | M44: 0.66322684 | N44: 0.10063029 | O44: 2025 | P44: 0.2672
A45: Cyprus | B45: 6.1300001 | C45: 1.8235354 | D45: 1.2244643 | E45: 0.57958376 | F45: 0.45541701 | G45: 0.049639788 | H45: 2024 | I45: 6.0681 | J45: 1.7937989 | K45: 1.2169918 | L45: 0.74399132 | M45: 0.52878994 | N45: 0.049175326 | O45: 2025 | P45: -0.0619
A46: Japan | B46: 6.1290002 | C46: 1.8251321 | D46: 1.3963242 | E46: 0.62174863 | F46: 0.55604839 | G46: 0.20712538 | H46: 2024 | I46: 6.0598001 | J46: 1.7857212 | K46: 1.3543787 | L46: 0.78483772 | M46: 0.63151836 | N46: 0.21942955 | O46: 2025 | P46: -0.0692
A47: Croatia | B47: 6.125 | C47: 1.7265333 | D47: 1.4545847 | E47: 0.47463068 | F47: 0.4996632 | G47: 0.002726536 | H47: 2024 | I47: 5.9422998 | J47: 1.7100956 | K47: 1.4447548 | L47: 0.63660008 | M47: 0.4691875 | N47: 0.04285844 | O47: 2025 | P47: -0.1827
A48: Brazil | B48: 6.1245999 | C48: 1.4544809 | D48: 1.2502195 | E48: 0.38740671 | F48: 0.55848819 | G48: 0.1370966 | H48: 2024 | I48: 6.2719998 | J48: 1.4295259 | K48: 1.2687776 | L48: 0.54791021 | M48: 0.68522376 | N48: 0.14245126 | O48: 2025 | P48: 0.1474
A49: El Salvador | B49: 6.1216002 | C49: 1.2776421 | D49: 1.0442631 | E49: 0.38327083 | F49: 0.71312326 | G49: 0.22166745 | H49: 2024 | I49: 6.4686999 | J49: 1.2650809 | K49: 1.0797729 | L49: 0.54873484 | M49: 0.8160305 | N49: 0.25271326 | O49: 2025 | P49: 0.3471
A50: Hungary | B50: 6.0412002 | C50: 1.7544873 | D50: 1.5188888 | E50: 0.43513578 | F50: 0.50058579 | G50: 0.064628392 | H50: 2024 | I50: 6.0169001 | J50: 1.7220712 | K50: 1.5282142 | L50: 0.59574205 | M50: 0.58092684 | N50: 0.067108043 | O50: 2025 | P50: -0.0243
A51: Argentina | B51: 6.0237002 | C51: 1.5895475 | D51: 1.3881742 | E51: 0.42695174 | F51: 0.58689874 | G51: 0.082425207 | H51: 2024 | I51: 6.1880999 | J51: 1.5617474 | K51: 1.3813045 | L51: 0.58465064 | M51: 0.68074375 | N51: 0.08045727 | O51: 2025 | P51: 0.1644
A52: Honduras | B52: 6.0225 | C52: 1.1148589 | D52: 1.0716113 | E52: 0.34147704 | F52: 0.6134178 | G52: 0.061733902 | H52: 2024 | I52: 5.9684 | J52: 1.0906942 | K52: 1.0354576 | L52: 0.50224245 | M52: 0.71987933 | N52: 0.08078099 | O52: 2025 | P52: -0.0541
A53: Uzbekistan | B53: 6.0142999 | C53: 1.2271769 | D53: 1.3474141 | E53: 0.37519485 | F53: 0.74024719 | G53: 0.20837432 | H53: 2024 | I53: 6.1950002 | J53: 1.2116952 | K53: 1.3944715 | L53: 0.53892112 | M53: 0.83495361 | N53: 0.21466397 | O53: 2025 | P53: 0.1807
... A78: Armenia | B78: 5.3417001 | C78: 1.4661459 | D78: 1.1339072 | E78: 0.44299701 | F78: 0.55087179 | G78: 0.16019709 | H78: 2024 | I78: 5.4548998 | J78: 1.4435884 | K78: 1.1544399 | L78: 0.60340416 | M78: 0.65023398 | N78: 0.17305009 | O78: 2025 | P78: 0.1132
A79: Tajikistan | B79: 5.3298001 | C79: 0.97186571 | D79: 1.2484393 | E79: 0.29141176 | F79: 0.59930676 | G79: 0.29188746 | H79: 2024 | I79: 5.2807002 | O79: 2025 | P79: -0.0491
A80: Algeria | B80: 5.3291001 | C80: 1.3533517 | D80: 1.2980682 | E80: 0.40921828 | F80: 0.25230396 | G80: 0.15197971 | H80: 2024 | I80: 5.3635001 | J80: 1.3235404 | K80: 1.1906074 | L80: 0.56790048 | M80: 0.24701156 | N80: 0.19999629 | O80: 2025 | P80: 0.0344
A81: Hong Kong | B81: 5.3084998 | C81: 1.9509403 | D81: 1.2013361 | E81: 0.70158988 | F81: 0.40679729 | G81: 0.38999292 | H81: 2024 | I81: 5.3164001 | J81: 1.9087111 | K81: 1.1844797 | L81: 0.85731542 | M81: 0.48470968 | N81: 0.40161422 | O81: 2025 | P81: 0.0079
A82: Albania | B82: 5.2772999 | C82: 1.4492034 | D82: 0.95122051 | E82: 0.48008245 | F82: 0.5491721 | G82: 0.036526635 | H82: 2024 | I82: 5.3042002 | J82: 1.4378889 | K82: 0.9235726 | L82: 0.63798749 | M82: 0.68972975 | N82: 0.048980724 | O82: 2025 | P82: 0.0269
A83: Indonesia | B83: 5.2768998 | C83: 1.3838159 | D83: 1.1686502 | E83: 0.3138144 | F83: 0.66332942 | G83: 0.038032882 | H83: 2024 | I83: 5.5682998 | J83: 1.3614945 | K83: 1.1842629 | L83: 0.47167096 | M83: 0.77944535 | N83: 0.054712676 | O83: 2025 | P83: 0.2914
A84: South Africa | B84: 5.2746 | C84: 1.4169476 | D84: 1.4279369 | E84: 0.148733 | F84: 0.46367109 | G84: 0.019301137 | H84: 2024 | I84: 5.4219999 | J84: 1.389106 | K84: 1.3692621 | L84: 0.32189444 | M84: 0.53659016 | N84: 0.033980638 | O84: 2025 | P84: 0.1474
A85: Congo (Brazzaville) | B85: 5.2670999 | C85: 0.92117816 | D85: 0.6650123 | E85: 0.14494769 | F85: 0.46362507 | G85: 0.13602151 | H85: 2024 | I85: 5.2214999 | J85: 0.89234102 | K85: 0.62188697 | L85: 0.30558527 | M85: 0.52273506 | N85: 0.13767824 | O85: 2025 | P85: -0.0456
A86: North Macedonia | B86: 5.2536001 | C86: 1.4978708 | D86: 1.1705784 | E86: 0.40788642 | F86: 0.5154193 | G86: 0.019607203 | H86: 2024 | I86: 5.3691001 | J86: 1.4753088 | K86: 1.2765878 | L86: 0.56937772 | M86: 0.57972711 | N86: 0.014632131 | O86: 2025 | P86: 0.1155
A87: Venezuela | B87: 5.2105999 | C87: 0 | D87: 1.2566576 | E87: 0.34111804 | F87: 0.36869797 | G87: 0.084272012 | H87: 2024 | I87: 5.6066999 | J87: 0 | K87: 1.3213502 | L87: 0.49113831 | M87: 0.51791286 | N87: 0.086161897 | O87: 2025 | P87: 0.3961
A88: Laos | B88: 5.1107001 | C88: 1.2321991 | D88: 0.85280114 | E88: 0.25653762 | F88: 0.7148841 | G88: 0.1622829 | H88: 2024 | I88: 5.1388998 | J88: 1.2084683 | K88: 0.84629792 | L88: 0.42291266 | M88: 0.79646611 | N88: 0.16654132 | O88: 2025 | P88: 0.0282
A89: Georgia | B89: 5.1090999 | C89: 1.4774613 | D89: 0.94683099 | E89: 0.3656463 | F89: 0.53871578 | G89: 0.20069587 | H89: 2024 | I89: 5.1847 | J89: 1.4669232 | K89: 0.99001116 | L89: 0.52437627 | M89: 0.67981416 | N89: 0.17428675 | O89: 2025 | P89: 0.0756
...

Sheet Dashboard
A1: World Happiness Report Dashboard | 2024 vs 2025 | AN1: Country Options
A2: Interactive dashboard built from WHR_Comparison_2024_vs_2025; raw data untouched. | AN2: All
A3: Country Filter | B3: All | D3: Year Filter | E3: 2025 | AN3: Finland
A4: Tip | B4: Use dropdowns/values to focus charts and KPIs | D4: Mode | E4: 2024 / 2025 / All | AN4: Denmark
AN5: Iceland
A6: Average Happiness Score 2024 | D6: Average Happiness Score 2025 | G6: Highest Happiness Score Country | J6: Largest Score Change | AN6: Norway
A7: =IF($B$3="All",AVERAGE(WHR_Comparison_2024_vs_2025!B3:B136),INDEX(WHR_Comparison_2024_vs_2025!B3:B136,MATCH($B$3,WHR_Comparison_2024_vs_2025!A3:A136,0))) -> 5.5149597 | D7: =IF($B$3="All",AVERAGE(WHR_Comparison_2024_vs_2025!I3:I136),INDEX(WHR_Comparison_2024_vs_2025!I3:I136,MATCH($B$3,WHR_Comparison_2024_vs_2025!A3:A136,0))) -> 5.5398201 | G7: =IF($B$3<>"All",$B$3&" ("&TEXT(IF($E$3="2024",INDEX(WHR_Comparison_2024_vs_2025!B3:B136,MATCH($B$3,WHR_Comparison_2024_vs_2025!A3:A136,0)),INDEX(WHR_Comparison_2024_vs_2025!I3:I136,MATCH($B$3,WHR_Comparison_2024_vs_2025!A3:A136,0))),"0.00")&")",IF($E$3="2024",INDEX(WHR_Comparison_2024_vs_2025!A3:A136,MATCH(MAX(WHR_Comparison_2024_vs_2025!B3:B136),WHR_Comparison_2024_vs_2025!B3:B136,0))&" ("&TEXT(MAX(WHR_Comparison_2024_vs_2025!B3:B136),"0.00")&")",INDEX(WHR_Comparison_2024_vs_2025!A3:A136,MATCH(MAX(WHR_Comparison_2024_vs_2025!I3:I136),WHR_Comparison_2024_vs_2025!I3:I136,0))&" ("&TEXT(MAX(WHR_Comparison_2024_vs_2025!I3:I136),"0.00")&")")) -> Finland (7.74) | J7: =IF($B$3<>"All",$B$3&" ("&TEXT(INDEX(WHR_Comparison_2024_vs_2025!P3:P136,MATCH($B$3,WHR_Comparison_2024_vs_2025!A3:A136,0)),"+0.00;-0.00;0.00")&")",IF(MAX(WHR_Comparison_2024_vs_2025!P3:P136)>=-MIN(WHR_Comparison_2024_vs_2025!P3:P136),INDEX(WHR_Comparison_2024_vs_2025!A3:A136,MATCH(MAX(WHR_Comparison_2024_vs_2025!P3:P136),WHR_Comparison_2024_vs_2025!P3:P136,0))&" ("&TEXT(MAX(WHR_Comparison_2024_vs_2025!P3:P136),"+0.00;-0.00;0.00")&")",INDEX(WHR_Comparison_2024_vs_2025!A3:A136,MATCH(MIN(WHR_Comparison_2024_vs_2025!P3:P136),WHR_Comparison_2024_vs_2025!P3:P136,0))&" ("&TEXT(MIN(WHR_Comparison_2024_vs_2025!P3:P136),"+0.00;-0.00;0.00")&")")) -> Sri Lanka (-0.54) | AN7: Netherlands
A8: Filtered by selected country | D8: Filtered by selected country | G8: Based on selected year | J8: Largest absolute 2024→2025 movement | AN8: Sweden
AN9: Switzerland
AN10: Luxembourg
AN11: New Zealand
AN12: Austria
AN13: Australia
AN14: Canada
AN15: Ireland
AN16: United States
AN17: Germany
AN18: Belgium
AN19: Czechia
AN20: United Kingdom
... AN58: Algeria
A59: Summary of Comparison of Both Years (2024 vs 2025) | AN59: Hong Kong
A60: Largest Score Changes | B60: Score 2024 | C60: Score 2025 | D60: Change | AN60: Albania
A61: Sri Lanka | B61: 4.4415998 | C61: 3.8980999 | D61: -0.5435 | AN61: Indonesia
A62: Philippines | B62: 5.5229001 | C62: 6.0475998 | D62: 0.5247 | AN62: South Africa
A63: Zambia | B63: 3.9821999 | C63: 3.5023999 | D63: -0.4798 | AN63: Congo (Brazzaville)
A64: Bangladesh | B64: 4.2821002 | C64: 3.8859 | D64: -0.3962 | AN64: North Macedonia
A65: Venezuela | B65: 5.2105999 | C65: 5.6066999 | D65: 0.3961 | AN65: Venezuela
A66: Turkiye | B66: 4.6135001 | C66: 4.9752998 | D66: 0.3618 | AN66: Laos
A67: Mexico | B67: 6.3295002 | C67: 6.678 | D67: 0.3485 | AN67: Georgia
A68: El Salvador | B68: 6.1216002 | C68: 6.4686999 | D68: 0.3471 | AN68: Guinea
A69: Costa Rica | B69: 6.6085 | C69: 6.9554 | D69: 0.3469 | AN69: Ukraine
A70: Ghana | B70: 4.605 | C70: 4.2894001 | D70: -0.3156 | AN70: Ivory Coast
A71: Peru | B71: 5.5258999 | C71: 5.8408999 | D71: 0.315 | AN71: Gabon
A72: Lebanon | B72: 2.3922 | C72: 2.7065001 | D72: 0.3143 | AN72: Nigeria
... A80: Ethiopia | B80: 4.0906 | C80: 3.8608999 | D80: -0.2297 | AN80: Mauritania
AN81: Burkina Faso
A83: Chart helper data (supports dashboard interactivity)
A84: Chart Helper Data | L84: Countries With Score Change
A85: Country | B85: Score 2024 | C85: Score 20242 | D85: Score Change | E85: Country2 | F85: Happiness Score | G85: GDP | H85: Happiness Score2 | I85: Freedom | J85: Happiness Score3 | L85: Country | M85: Score Change
...
